# 异常处理

## 介绍
异常是程序中的一些错误，但并不是所有的错误都是异常，并且错误有时候是可以避免的。

比如说，你用print(11/0)，那么你是因为你用0做了除数，会抛出 Ve.DivideByZeroException 的异常。

## 异常类
下面的表中列出了Ve 的异常类。
|异常类	|描述|
|-|-|
|Ve.IndexOutOfRangeException|处理当方法指向超出范围的数组索引时生成的错误。
|Ve.ArrayTypeMismatchException|处理当数组类型不匹配时生成的错误。
|Ve.NullReferenceException|处理当依从一个空对象时生成的错误。
|Ve.DivideByZeroException|处理当除以零时生成的错误。
|Ve.InvalidCastException|处理在类型转换期间生成的错误。

## 捕获异常
语法:
```
try{
   // 引起异常的语句
}
catch(ExceptionName e1){
   // 错误处理代码
}
...
catch(ExceptionName e1){
   // 错误处理代码
}
finally{
   // 要执行的语句
}
```

try语句包含了由一个或者多个语句组成的try块, 和至少一个catch子句或者一个finally子句的其中一个，或者两个兼有， 下面是三种形式的try声明：

1. try...catch
2. try...finally
3. try...catch...finally
catch子句包含try块中抛出异常时要执行的语句。也就是，你想让try语句中的内容成功， 如果没成功，你想控制接下来发生的事情，这时你可以在catch语句中实现。 如果在try块中有任何一个语句（或者从try块中调用的函数）抛出异常，控制立即转向catch子句。如果在try块中没有异常抛出，会跳过catch子句。

finally子句在try块和catch块之后执行但是在下一个try声明之前执行。无论是否有异常抛出或捕获它总是执行。

你可以嵌套一个或者更多的try语句。如果内部的try语句没有catch子句，那么将会进入包裹它的try语句的catch子句。

